Workbook
Name Actual: (PeriodInActual*(#REF!>0))*PeriodInPlan
Name ActualBeyond: PeriodInActual*(#REF!>0)
Name PercentComplete: PercentCompleteBeyond*PeriodInPlan
Name PercentCompleteBeyond: (#REF!=MEDIAN(#REF!,#REF!,#REF!+#REF!)*(#REF!>0))*((#REF!<(INT(#REF!+#REF!*#REF!)))+(#REF!=#REF!))*(#REF!>0)
Name period_selected: #REF!
Name PeriodInActual: #REF!=MEDIAN(#REF!,#REF!,#REF!+#REF!-1)
Name PeriodInPlan: #REF!=MEDIAN(#REF!,#REF!,#REF!+#REF!-1)
Name Plan: PeriodInPlan*(#REF!>0)

Sheet Summary & Hardening
A1: ITEMS | B1: UCS SETTING | C1: UCS SETTING FORMATTED (ENABLE WRAP TEXT) | D1: CIS SETTING | E1: COMPLIANT/ NON-COMPLIANT/ DEVIATE | F1: CIS RECOMMENDATION | G1: CIS DESCRIPTION | H1: CIS RATIONALE | I1: CIS IMPACT | J1: CIS REFERENCE
A2: SYSTEM INFORMATION
A3: Hostname | B3: {=Hostname[HOSTNAME]} -> #VALUE! | D3: - | E3: - | F3: - | G3: - | H3: - | I3: - | J3: -
A4: Management Port IP Address | B4: {=IFERROR(MgmtIP[MGMT IP],'cmdevice'!K2)} -> #VALUE! | D4: - | E4: - | F4: - | G4: - | H4: - | I4: - | J4: -
A5: Management Port Net Mask | B5: {=MgmtIP[CIDR]} -> #VALUE! | D5: - | E5: - | F5: - | G5: - | H5: - | I5: - | J5: -
A6: Management Gateway | B6: =_xlfn.XLOOKUP("sys management-route /Common/default*",MgmtRoute[PASTE ONE LINE CONFIG HERE],MgmtRoute[GATEWAY IP],,2) -> #N/A | D6: - | E6: - | F6: - | G6: - | H6: - | I6: - | J6: -
A7: Module | B7: =SUBSTITUTE(_xlfn.CONCAT(Provision[PASTE ONE LINE CONFIG HERE]),"}s","}"&CHAR(10)&"s") | D7: - | E7: - | F7: - | G7: - | H7: - | I7: - | J7: -
A8: Software Version | B8: ='cmdevice'!R2 -> #VALUE! | D8: - | E8: - | F8: - | G8: - | H8: - | I8: - | J8: -
A9: Build | B9: ='cmdevice'!F2 -> #VALUE! | D9: - | E9: - | F9: - | G9: - | H9: - | I9: - | J9: -
A10: Serial Number | B10: =VLOOKUP("/common/"&B3,CMDevice[[#All],[cm device ]:[ chassis-id ]],5,FALSE) -> #VALUE! | D10: - | E10: - | F10: - | G10: - | H10: - | I10: - | J10: -
A11: DEVICE CERTIFICATE
A12: Subject | B12: =VLOOKUP("server.crt",DeviceCertificateDetails[],3,FALSE) -> #N/A | D12: - | E12: - | F12: - | G12: - | H12: - | I12: - | J12: -
A13: Issuer | B13: =VLOOKUP("server.crt",DeviceCertificateDetails[],4,FALSE) -> #N/A | D13: - | E13: - | F13: - | G13: - | H13: - | I13: - | J13: -
A14: Not After | B14: =VLOOKUP("server.crt",DeviceCertificateDetails[],7,FALSE) -> #N/A | D14: - | E14: - | F14: - | G14: - | H14: - | I14: - | J14: -
A15: SAN | B15: =VLOOKUP("server.crt",DeviceCertificateDetails[],8,FALSE) -> #N/A | D15: - | E15: - | F15: - | G15: - | H15: - | I15: - | J15: -
A16: DEVICE CONFIGURATION SUMMARY
A17: No of Device | B17: =COUNTA(CMDevice[PASTE ONE LINE CONFIG HERE]) -> 0 | D17: - | E17: - | F17: - | G17: - | H17: - | I17: - | J17: -
A18: NETWORK CONFIGURATION SUMMARY
A19: No of VLAN | B19: =COUNTA(VLAN[PASTE ONE LINE CONFIG HERE]) -> 0 | D19: - | E19: - | F19: - | G19: - | H19: - | I19: - | J19: -
A20: No of Self IP | B20: =COUNTA(SelfIP[PASTE ONE LINE CONFIG HERE]) -> 0 | D20: - | E20: - | F20: - | G20: - | H20: - | I20: - | J20: -
A21: No of Route | B21: =COUNTA(Route[PASTE ONE LINE CONFIG HERE]) -> 0 | D21: - | E21: - | F21: - | G21: - | H21: - | I21: - | J21: -
A22: No of Mgmt Route | B22: =COUNTA(MgmtRoute[PASTE ONE LINE CONFIG HERE]) -> 0 | D22: - | E22: - | F22: - | G22: - | H22: - | I22: - | J22: -
A23: LTM CONFIGURATION SUMMARY
A24: No of Virtual Servers | B24: =COUNTA(VirtualServer[PASTE ONE LINE CONFIG HERE]) -> 0 | D24: - | E24: - | F24: - | G24: - | H24: - | I24: - | J24: -
A25: No of Virtual Servers using automap | B25: =COUNTIF(VirtualServer[SNAT],"type automap") -> 0 | D25: - | E25: - | F25: - | G25: - | H25: - | I25: - | J25: -
A26: No of Virtual Servers using SNAT pool | B26: =COUNTIF(VirtualServer[SNAT],"*type snat*") -> 0 | D26: - | E26: - | F26: - | G26: - | H26: - | I26: - | J26: -
A27: No of Pools | B27: =COUNTA(Pool[PASTE ONE LINE CONFIG HERE]) -> 0 | D27: - | E27: - | F27: - | G27: - | H27: - | I27: - | J27: -
A28: No of SNAT Pools | B28: =COUNTA(SNAT[PASTE ONE LINE CONFIG HERE]) -> 0 | D28: - | E28: - | F28: - | G28: - | H28: - | I28: - | J28: -
A29: No of ClientSSL Profiles | B29: =COUNTA(ClientSSL[PASTE ONE LINE CONFIG HERE]) -> 0 | D29: - | E29: - | F29: - | G29: - | H29: - | I29: - | J29: -
A30: No of Certs | B30: =COUNTA(Cert[PASTE ONE LINE CONFIG HERE]) -> 0 | D30: - | E30: - | F30: - | G30: - | H30: - | I30: - | J30: -
A31: No of Keys | B31: =COUNTA(Key[PASTE ONE LINE CONFIG HERE]) -> 0 | D31: - | E31: - | F31: - | G31: - | H31: - | I31: - | J31: -
A32: GTM CONFIGURATION SUMMARY
A33: No of Datacenter | B33: =COUNTA(gtmdatacenter[PASTE ONE LINE CONFIG HERE]) -> 0 | D33: - | E33: - | F33: - | G33: - | H33: - | I33: - | J33: -
A34: No of Prober Pool | B34: =COUNTA(gtmproberpool[PASTE ONE LINE CONFIG HERE]) -> 0 | D34: - | E34: - | F34: - | G34: - | H34: - | I34: - | J34: -
A35: No of Server | B35: =COUNTA(gtmserver[PASTE ONE LINE CONFIG HERE]) -> 0 | D35: - | E35: - | F35: - | G35: - | H35: - | I35: - | J35: -
A36: No of Topology | B36: =COUNTA(gtmtopology[PASTE ONE LINE CONFIG HERE]) -> 0 | D36: - | E36: - | F36: - | G36: - | H36: - | I36: - | J36: -
A37: No of Pool | B37: =COUNTA(gtmpool[PASTE ONE LINE CONFIG HERE]) -> 0 | D37: - | E37: - | F37: - | G37: - | H37: - | I37: - | J37: -
A38: No of Wide IP | B38: =COUNTA(gtmwideip[PASTE ONE LINE CONFIG HERE]) -> 0 | D38: - | E38: - | F38: - | G38: - | H38: - | I38: - | J38: -
A39: PASSWORD POLICY
A40: Password Policy | B40: {=PasswordPolicy[Replace last } with " }"]} -> #VALUE! | C40: =SUBSTITUTE(SUBSTITUTE(SUBSTITUTE(SUBSTITUTE(SUBSTITUTE(SUBSTITUTE(SUBSTITUTE(SUBSTITUTE(SUBSTITUTE(SUBSTITUTE(SUBSTITUTE(SUBSTITUTE(SUBSTITUTE(B40," "," "&CHAR(10),3)," "," "&CHAR(10),5)," "," "&CHAR(10),7)," "," "&CHAR(10),9)," "," "&CHAR(10),11)," "," "&CHAR(10),13)," "," "&CHAR(10),15)," "," "&CHAR(10),17)," "," "&CHAR(10),19)," "," "&CHAR(10),21)," "," "&CHAR(10),23)," "," "&CHAR(10),25)," "," "&CHAR(10),27) -> #VALUE! | D40: auth password-policy { expiration-warning 14 lockout-duration 300 manual-unlock-disabled true max-duration 180 max-login-failures 3 min-duration 90 minimum-length 12 password-memory 24 required-lowercase 1 required-numeric 1 required-special 1 required-uppercase 1 } | F40: 1.1.3 Configure Secure Password Policy (Manual) | G40: To assist users in maintaining strong passwords, ensure that passwords are changed at appropriate intervals and new passwords to be used | H40: Having a weak or non-existent password policy will allow users to use weak or easily cracked passwords. | I40: Without proper password management the users are more likely to select weak passwords or forget complex passwords. This can create security risks as these passwords make it easier for attackers to crack. | J40: https://support.f5.com/csp/article/K15497
...

Sheet DeviceManagement>>>>>>>>>>>>>>>

Sheet cmdevice
A1: PASTE ONE LINE CONFIG HERE | B1: Replace last } with " }" | C1: cm device | D1: active-modules { " | E1: base-mac | F1: build | G1: chassis-id | H1: chassis-type | I1: configsync-ip | J1: hostname | K1: management-ip | L1: marketing-name " | M1: mirror-ip | N1: platform-id | O1: product | P1: time-zone | Q1: unicast-address { { | R1: version
B2: =LEFT(A2,LEN(A2)-1)&" }" -> #VALUE! | C2: =MID($B2,FIND(C$1,$B2)+LEN(C$1),FIND(" ",$B2,FIND(C$1,$B2)+LEN(C$1))-FIND(C$1,$B2)-LEN(C$1)) -> #VALUE! | D2: =MID($B2,FIND(D$1,$B2)+LEN(D$1),FIND(CHAR(34),$B2,FIND(D$1,$B2)+LEN(D$1))-FIND(D$1,$B2)-LEN(D$1)) -> #VALUE! | E2: =MID($B2,FIND(E$1,$B2)+LEN(E$1),FIND(" ",$B2,FIND(E$1,$B2)+LEN(E$1))-FIND(E$1,$B2)-LEN(E$1)) -> #VALUE! | F2: =MID($B2,FIND(F$1,$B2)+LEN(F$1),FIND(" ",$B2,FIND(F$1,$B2)+LEN(F$1))-FIND(F$1,$B2)-LEN(F$1)) -> #VALUE! | G2: =SUBSTITUTE(MID($B2,FIND(G$1,$B2)+LEN(G$1),FIND(" ",$B2,FIND(G$1,$B2)+LEN(G$1))-FIND(G$1,$B2)-LEN(G$1)),CHAR(34),"") -> #VALUE! | H2: =MID($B2,FIND(H$1,$B2)+LEN(H$1),FIND(" ",$B2,FIND(H$1,$B2)+LEN(H$1))-FIND(H$1,$B2)-LEN(H$1)) -> #VALUE! | I2: =MID($B2,FIND(I$1,$B2)+LEN(I$1),FIND(" ",$B2,FIND(I$1,$B2)+LEN(I$1))-FIND(I$1,$B2)-LEN(I$1)) -> #VALUE! | J2: =MID($B2,FIND(J$1,$B2)+LEN(J$1),FIND(" ",$B2,FIND(J$1,$B2)+LEN(J$1))-FIND(J$1,$B2)-LEN(J$1)) -> #VALUE! | K2: =MID($B2,FIND(K$1,$B2)+LEN(K$1),FIND(" ",$B2,FIND(K$1,$B2)+LEN(K$1))-FIND(K$1,$B2)-LEN(K$1)) -> #VALUE! | L2: =MID($B2,FIND(L$1,$B2)+LEN(L$1),FIND(CHAR(34),$B2,FIND(L$1,$B2)+LEN(L$1))-FIND(L$1,$B2)-LEN(L$1)) -> #VALUE! | M2: =MID($B2,FIND(M$1,$B2)+LEN(M$1),FIND(" ",$B2,FIND(M$1,$B2)+LEN(M$1))-FIND(M$1,$B2)-LEN(M$1)) -> #VALUE! | N2: =MID($B2,FIND(N$1,$B2)+LEN(N$1),FIND(" ",$B2,FIND(N$1,$B2)+LEN(N$1))-FIND(N$1,$B2)-LEN(N$1)) -> #VALUE! | O2: =MID($B2,FIND(O$1,$B2)+LEN(O$1),FIND(" ",$B2,FIND(O$1,$B2)+LEN(O$1))-FIND(O$1,$B2)-LEN(O$1)) -> #VALUE! | P2: =MID($B2,FIND(P$1,$B2)+LEN(P$1),FIND(" ",$B2,FIND(P$1,$B2)+LEN(P$1))-FIND(P$1,$B2)-LEN(P$1)) -> #VALUE! | Q2: =MID($B2,FIND(Q$1,$B2)+LEN(Q$1),FIND(" } } ",$B2,FIND(Q$1,$B2)+LEN(Q$1))-FIND(Q$1,$B2)-LEN(Q$1)) -> #VALUE! | R2: =MID($B2,FIND(R$1,$B2)+LEN(R$1),FIND(" ",$B2,FIND(R$1,$B2)+LEN(R$1))-FIND(R$1,$B2)-LEN(R$1)) -> #VALUE!

Sheet cmdevicegroup
A1: PASTE ONE LINE CONFIG HERE | B1: Replace last } with " }" | C1: cm device-group | D1: auto-sync | E1: devices { | F1: type | G1: network-failover
B2: =LEFT(A2,LEN(A2)-1)&" }" -> #VALUE! | C2: =IFERROR(MID($B2,FIND(C$1,$B2)+LEN(C$1),FIND(" ",$B2,FIND(C$1,$B2)+LEN(C$1))-FIND(C$1,$B2)-LEN(C$1)),"") | D2: =IFERROR(MID($B2,FIND(D$1,$B2)+LEN(D$1),FIND(" ",$B2,FIND(D$1,$B2)+LEN(D$1))-FIND(D$1,$B2)-LEN(D$1)),"") | E2: =IFERROR(MID($B2,FIND(E$1,$B2)+LEN(E$1),FIND(" { } } ",$B2,FIND(E$1,$B2)+LEN(E$1))-FIND(E$1,$B2)-LEN(E$1)),"") | F2: =IFERROR(MID($B2,FIND(F$1,$B2)+LEN(F$1),FIND(" ",$B2,FIND(F$1,$B2)+LEN(F$1))-FIND(F$1,$B2)-LEN(F$1)),"") | G2: =IFERROR(MID($B2,FIND(G$1,$B2)+LEN(G$1),FIND(" ",$B2,FIND(G$1,$B2)+LEN(G$1))-FIND(G$1,$B2)-LEN(G$1)),"")

Sheet cmtrafficgroup
A1: PASTE ONE LINE CONFIG HERE | B1: Replace last } with " }" | C1: cm traffic-group
B2: =LEFT(A2,LEN(A2)-1)&" }" -> #VALUE! | C2: =IFERROR(MID($B2,FIND(C$1,$B2)+LEN(C$1),FIND(" ",$B2,FIND(C$1,$B2)+LEN(C$1))-FIND(C$1,$B2)-LEN(C$1)),"")

Sheet cmtrustdomain
A1: PASTE ONE LINE CONFIG HERE | B1: Replace last } with " }" | C1: cm trust-domain
B2: =LEFT(A2,LEN(A2)-1)&" }" -> #VALUE! | C2: =IFERROR(MID($B2,FIND(C$1,$B2)+LEN(C$1),FIND(" ",$B2,FIND(C$1,$B2)+LEN(C$1))-FIND(C$1,$B2)-LEN(C$1)),"")

Sheet sysstatemirroring
A1: PASTE ONE LINE CONFIG HERE | B1: Replace last } with " }"
B2: =LEFT(A2,LEN(A2)-1)&" }" -> #VALUE!

Sheet System>>>>>>>>>>>>>>>>>>>>>>>>>

Sheet hostname
A1: PASTE ONE LINE CONFIG HERE | B1: Replace last } with " }" | C1: HOSTNAME
B2: =LEFT(A2,LEN(A2)-1)&" }" -> #VALUE! | C2: =IFERROR(MID(MID(B2,FIND("hostname ",B2)+9,100),1,FIND(" ",MID(B2,FIND("hostname ",B2)+9,100))-1),MID(MID(B2,FIND("hostname ",B2)+9,100),1,FIND(" ",MID(B2,FIND("hostname ",B2)+9,100))-1)) -> #VALUE!

Sheet partition
A1: PASTE ONE LINE CONFIG HERE | B1: Replace last } with " }" | C1: NAME | D1: DESCRIPTION
B2: =LEFT(A2,LEN(A2)-1)&" }" -> #VALUE! | C2: =MID(A2,FIND("auth partition ",A2)+15,FIND(" ",A2,FIND("auth partition ",A2)+15)-FIND("auth partition ",A2)-15) -> #VALUE! | D2: =MID(B2,FIND("description ",B2)+12,FIND("}",B2,FIND("description ",B2)+12)-FIND("description ",B2)-12) -> #VALUE!

Sheet securityfwmgmtip
A1: PASTE ONE LINE CONFIG HERE | B1: Replace last } with " }" | C1: RULES
B2: =LEFT(A2,LEN(A2)-1)&" }" -> #VALUE! | C2: =SUBSTITUTE(SUBSTITUTE(SUBSTITUTE(B2,"{ } } } } ","}"&CHAR(10)),"{ } } } ","}"&CHAR(10))," rules { ",CHAR(10)) -> #VALUE!

Sheet mgmtip
A1: PASTE ONE LINE CONFIG HERE | B1: MGMT IP/CIDR | C1: MGMT IP | D1: CIDR
B2: =MID(MID(A2,FIND("management-ip ",A2)+14,100),1,FIND(" ",MID(A2,FIND("management-ip ",A2)+14,100))-1) -> #VALUE! | C2: =MID(B2,1,FIND("/",B2)-1) -> #VALUE! | D2: =MID(B2,FIND("/",B2),10) -> #VALUE!

Sheet mgmtroute
A1: PASTE ONE LINE CONFIG HERE | B1: GATEWAY IP
B2: =MID(MID(A2,FIND("gateway ",A2)+8,100),1,FIND(" ",MID(A2,FIND("gateway ",A2)+8,100))-1) -> #VALUE!

Sheet provision
A1: PASTE ONE LINE CONFIG HERE

Sheet ntp
A1: PASTE ONE LINE CONFIG HERE | B1: SERVER IP
B2: =MID(MID(A2,FIND("servers { ",A2)+10,100),1,FIND("}",MID(A2,FIND("servers { ",A2)+10,100))-2) -> #VALUE!

Sheet dns
A1: PASTE ONE LINE CONFIG HERE | B1: SERVER IP
B2: =MID(MID(A2,FIND("servers { ",A2)+10,100),1,FIND("}",MID(A2,FIND("servers { ",A2)+10,100))-2) -> #VALUE!

Sheet syslog
A1: PASTE ONE LINE CONFIG HERE

Sheet snmp
A1: PASTE ONE LINE CONFIG HERE

Sheet user
A1: PASTE ONE LINE CONFIG HERE | B1: Replace last } with " }" | C1: USERNAME | D1: PARTITION | E1: SHELL
B2: =LEFT(A2,LEN(A2)-1)&" }" -> #VALUE! | C2: =MID(A2,FIND("auth user ",A2)+10,FIND(" ",A2,FIND("auth user ",A2)+10)-FIND("auth user ",A2)-10) -> #VALUE! | D2: =MID(A2,FIND("partition-access {",A2)+19,FIND(" } } ",A2,FIND("partition-access { ",A2)+19)-FIND("partition-access {",A2)-19) -> #VALUE! | E2: =MID(B2,FIND("shell ",B2)+6,FIND(" ",B2,FIND("shell ",B2)+6)-FIND("shell ",B2)-6) -> #VALUE!

Sheet passwordpolicy
A1: PASTE ONE LINE CONFIG HERE | B1: Replace last } with " }"
B2: =LEFT(A2,LEN(A2)-1)&" }" -> #VALUE!

Sheet httpd
A1: PASTE ONE LINE CONFIG HERE | B1: Replace last } with " }"
B2: =LEFT(A2,LEN(A2)-1)&" }" -> #VALUE!

Sheet sshd
A1: PASTE ONE LINE CONFIG HERE | B1: Replace last } with " }"
B2: =LEFT(A2,LEN(A2)-1)&" }" -> #VALUE!

Sheet cliglobalsettings
A1: PASTE ONE LINE CONFIG HERE | B1: Replace last } with " }"
B2: =LEFT(A2,LEN(A2)-1)&" }" -> #VALUE!

Sheet sysglobalsettings
A1: PASTE ONE LINE CONFIG HERE | B1: Replace last } with " }"
B2: =LEFT(A2,LEN(A2)-1)&" }" -> #VALUE!

Sheet auth
A1: PASTE ONE LINE CONFIG HERE | B1: Replace last } with " }"
B2: =LEFT(A2,LEN(A2)-1)&" }" -> #VALUE!

Sheet devicecert
A1: FileName | B1: FilePath | C1: Subject | D1: Issuer | E1: Thumbprint | F1: NotBefore | G1: NotAfter | H1: SAN

Sheet cert
A1: PASTE ONE LINE CONFIG HERE | B1: NAME | C1: CACHE PATH
B2: =MID(A2,FIND("ssl-cert /",A2)+9,FIND(" ",A2,FIND("ssl-cert /",A2)+9)-FIND("ssl-cert /",A2)-9) -> #VALUE! | C2: =MID(A2,FIND("cache-path /",A2)+11,FIND(" ",A2,FIND("cache-path /",A2)+11)-FIND("cache-path /",A2)-11) -> #VALUE!

Sheet certdetails
A1: FileName | B1: FilePath | C1: Subject | D1: Issuer | E1: Thumbprint | F1: NotBefore | G1: NotAfter | H1: SAN | I1: SAN without CHAR(10)
I2: =SUBSTITUTE(CertificateDetails[[#This Row],[SAN]],CHAR(10),"")

Sheet key
A1: PASTE ONE LINE CONFIG HERE | B1: NAME | C1: CACHE PATH
B2: =MID(A2,FIND("ssl-key /",A2)+8,FIND(" ",A2,FIND("ssl-key /",A2)+8)-FIND("ssl-key /",A2)-8) -> #VALUE! | C2: =MID(A2,FIND("cache-path /",A2)+11,FIND(" ",A2,FIND("cache-path /",A2)+11)-FIND("cache-path /",A2)-11) -> #VALUE!

Sheet DB>>>>>>>>>>>>>>>>>>>>>>>>>>>>>

Sheet uilogaccess
A1: PASTE ONE LINE CONFIG HERE | B1: ROLE | C1: DEFAULT | D1: COMBINED
B2: =MID(A2,FIND("UI.logAccess.",A2)+13,FIND(":",A2,FIND("UI.logAccess.",A2)+13)-FIND("UI.logAccess.",A2)-14) -> #VALUE! | C2: =MID(A2,FIND("default=",A2)+8,FIND(":",A2,FIND("default=",A2)+8)-FIND("default=",A2)-8) -> #VALUE! | D2: =UIlogAccess[[#This Row],[ROLE]]&":"&UIlogAccess[[#This Row],[DEFAULT]]&"@" -> #VALUE!

Sheet configauditing
A1: PASTE ONE LINE CONFIG HERE | B1: DB | C1: DEFAULT
B2: =MID(A2,FIND("[Config.Auditing]",A2),FIND(":",A2,FIND("[Config.Auditing]",A2))-FIND("[Config.Auditing]",A2)) -> #VALUE! | C2: =MID(A2,FIND("default=",A2)+8,FIND(":",A2,FIND("default=",A2)+8)-FIND("default=",A2)-8) -> #VALUE!

Sheet Network>>>>>>>>>>>>>>>>>>>>>>>>

Sheet trunk
A1: PASTE ONE LINE CONFIG HERE | B1: TRUNK NAME | C1: INTERFACE | D1: LACP
B2: =MID(MID(A2,FIND("net trunk ",A2)+10,100),1,FIND(" ",MID(A2,FIND("net trunk ",A2)+10,100))-1) -> #VALUE! | C2: =MID(MID(A2,FIND("interfaces { ",A2)+13,100),1,FIND("}",MID(A2,FIND("interfaces { ",A2)+13,100))-2) -> #VALUE! | D2: =IFERROR(MID(MID(A2,FIND("lacp ",A2)+5,100),1,FIND(" ",MID(A2,FIND("lacp ",A2)+5,100))-2),MID(MID(A2,FIND("lacp ",A2)+5,100),1,FIND("}",MID(A2,FIND("lacp ",A2)+5,100))-2)) -> #VALUE!

Sheet netroutedomain
A1: PASTE ONE LINE CONFIG HERE | B1: Replace last } with " }" | C1: net route-domain | D1: vlans {
B2: =LEFT(A2,LEN(A2)-1)&" }" -> #VALUE! | C2: =IFERROR(MID($B2,FIND(C$1,$B2)+LEN(C$1),FIND(" ",$B2,FIND(C$1,$B2)+LEN(C$1))-FIND(C$1,$B2)-LEN(C$1)),"") | D2: =IFERROR(MID($B2,FIND(D$1,$B2)+LEN(D$1),FIND(" } }",$B2,FIND(D$1,$B2)+LEN(D$1))-FIND(D$1,$B2)-LEN(D$1)),"")

Sheet nettunnels
A1: PASTE ONE LINE CONFIG HERE | B1: Replace last } with " }" | C1: net tunnels tunnel | D1: description " | E1: profile
B2: =LEFT(A2,LEN(A2)-1)&" }" -> #VALUE! | C2: =IFERROR(MID($B2,FIND(C$1,$B2)+LEN(C$1),FIND(" ",$B2,FIND(C$1,$B2)+LEN(C$1))-FIND(C$1,$B2)-LEN(C$1)),"") | D2: =IFERROR(MID($B2,FIND(D$1,$B2)+LEN(D$1),FIND(CHAR(34),$B2,FIND(D$1,$B2)+LEN(D$1))-FIND(D$1,$B2)-LEN(D$1)),"") | E2: =IFERROR(MID($B2,FIND(E$1,$B2)+LEN(E$1),FIND(" ",$B2,FIND(E$1,$B2)+LEN(E$1))-FIND(E$1,$B2)-LEN(E$1)),"")

Sheet vlan
A1: PASTE ONE LINE CONFIG HERE | B1: VLAN NAME | C1: FAILSAFE | D1: FAILSAFE ACTION | E1: FAILSAFE TIMEOUT | F1: INTERFACE | G1: TAG | H1: VLAN ID
B2: =LEFT(SUBSTITUTE(A2,"net vlan /Common/",""),FIND(" ",SUBSTITUTE(A2,"net vlan /Common/",""))-1) -> #VALUE! | C2: =IFERROR(MID(MID(A2,FIND(" failsafe ",A2)+10,50),1,FIND(" ",MID(A2,FIND(" failsafe ",A2)+10,50))),"") | D2: =IFERROR(MID(MID(A2,FIND(" failsafe-action ",A2)+17,50),1,FIND(" ",MID(A2,FIND(" failsafe-action ",A2)+17,50))),"") | E2: =IFERROR(MID(MID(A2,FIND(" failsafe-timeout ",A2)+18,50),1,FIND(" ",MID(A2,FIND(" failsafe-timeout ",A2)+18,50))-1),"") | F2: =IFERROR(MID(MID(A2,FIND(" interfaces {",A2)+14,50),1,FIND("} }",MID(A2,FIND(" interfaces {",A2)+14,50))),"") | G2: =IFERROR(MID(F2,FIND(" tagged ",F2)+1,6),"untagged") -> untagged | H2: =MID(MID(A2,FIND(" tag ",A2)+5,50),1,FIND("}",MID(A2,FIND(" tag ",A2)+5,50))-1) -> #VALUE!

Sheet selfip
A1: PASTE ONE LINE CONFIG HERE | B1: SELF IP NAME | C1: SELF IP ADDRESS/CIDR | D1: ALLOW SERVICE | E1: TRAFFIC GROUP | F1: VLAN
B2: =LEFT(SUBSTITUTE(A2,"net self /Common/",""),FIND(" ",SUBSTITUTE(A2,"net self /Common/",""))-1) -> #VALUE! | C2: =MID(MID(A2,FIND("{ address ",A2,1)+10,100),1,FIND(" ",MID(A2,FIND("{ address ",A2,1)+10,100))-1) -> #VALUE! | D2: =IFERROR(MID(MID(A2,FIND("allow-service ",A2)+14,200),1,FIND(" traffic-group ",MID(A2,FIND("allow-service ",A2)+14,200))-1),"none") -> none | E2: =MID(MID(A2,FIND("traffic-group /",A2)+22,200),1,FIND(" ",MID(A2,FIND("traffic-group /",A2)+22,200))-1) -> #VALUE! | F2: =SUBSTITUTE(MID(A2,FIND("vlan /Common",A2)+13,200),"}","") -> #VALUE!

Sheet route
A1: PASTE ONE LINE CONFIG HERE | B1: Replace last } with " }" | C1: NAME | D1: GATEWAY IP | E1: NETWORK
B2: =LEFT(A2,LEN(A2)-1)&" }" -> #VALUE! | C2: =MID(A2,FIND("net route /",A2)+11,FIND(" ",A2,FIND("net route /",A2)+11)-FIND("net route /",A2)-11) -> #VALUE! | D2: =MID(A2,FIND(" gw ",A2)+4,FIND(" ",A2,FIND(" gw ",A2)+4)-FIND(" gw ",A2)-4) -> #VALUE! | E2: =MID(B2,FIND(" network ",B2)+9,FIND(" ",B2,FIND(" network ",B2)+9)-FIND(" network ",B2)-9) -> #VALUE!

Sheet LTM>>>>>>>>>>>>>>>>>>>>>>>>>>>>

Sheet defaultprofile
A1: PROFILE NAME | B1: TYPE | C1: REMARKS
A2: /Common/http | B2: http | C2: Default profile not shown in bigip.conf
A3: /Common/http-explicit | B3: http | C3: Default profile not shown in bigip.conf
A4: /Common/http-transparent | B4: http | C4: Default profile not shown in bigip.conf
A5: /Common/apm-forwarding-client-tcp | B5: tcp | C5: Default profile not shown in bigip.conf
A6: /Common/apm-forwarding-server-tcp | B6: tcp | C6: Default profile not shown in bigip.conf
A7: /Common/f5-tcp-lan | B7: tcp | C7: Default profile not shown in bigip.conf
A8: /Common/f5-tcp-mobile | B8: tcp | C8: Default profile not shown in bigip.conf
A9: /Common/f5-tcp-progressive | B9: tcp | C9: Default profile not shown in bigip.conf
A10: /Common/f5-tcp-wan | B10: tcp | C10: Default profile not shown in bigip.conf
A11: /Common/mptcp-mobile-optimized | B11: tcp | C11: Default profile not shown in bigip.conf
A12: /Common/splitsession-default-tcp | B12: tcp | C12: Default profile not shown in bigip.conf
... A41: /Common/wom-default-serverssl { context serverside } | B41: server-ssl | C41: Default profile not shown in bigip.conf

Sheet baseprofile
A1: PASTE ONE LINE CONFIG HERE | B1: TYPE | C1: PROFILE NAME
A2: ltm profile certificate-authority certificateauthority { | B2: =MID(A2,FIND("ltm profile ",A2)+12,FIND(" ",A2,FIND("ltm profile ",A2)+12)-FIND("ltm profile ",A2)-12) -> certificate-authority | C2: {=INDEX(_xlfn.TEXTSPLIT(A2, " "), 4)} -> certificateauthority
A3: ltm profile client-ssl clientssl { | B3: =MID(A3,FIND("ltm profile ",A3)+12,FIND(" ",A3,FIND("ltm profile ",A3)+12)-FIND("ltm profile ",A3)-12) -> client-ssl | C3: {=INDEX(_xlfn.TEXTSPLIT(A3, " "), 4)} -> clientssl
A4: ltm profile client-ssl clientssl-legacy { | B4: =MID(A4,FIND("ltm profile ",A4)+12,FIND(" ",A4,FIND("ltm profile ",A4)+12)-FIND("ltm profile ",A4)-12) -> client-ssl | C4: {=INDEX(_xlfn.TEXTSPLIT(A4, " "), 4)} -> clientssl-legacy
A5: ltm profile client-ssl clientssl-insecure-compatible { | B5: =MID(A5,FIND("ltm profile ",A5)+12,FIND(" ",A5,FIND("ltm profile ",A5)+12)-FIND("ltm profile ",A5)-12) -> client-ssl | C5: {=INDEX(_xlfn.TEXTSPLIT(A5, " "), 4)} -> clientssl-insecure-compatible
A6: ltm profile client-ssl wom-default-clientssl { | B6: =MID(A6,FIND("ltm profile ",A6)+12,FIND(" ",A6,FIND("ltm profile ",A6)+12)-FIND("ltm profile ",A6)-12) -> client-ssl | C6: {=INDEX(_xlfn.TEXTSPLIT(A6, " "), 4)} -> wom-default-clientssl
A7: ltm profile client-ssl crypto-server-default-clientssl { | B7: =MID(A7,FIND("ltm profile ",A7)+12,FIND(" ",A7,FIND("ltm profile ",A7)+12)-FIND("ltm profile ",A7)-12) -> client-ssl | C7: {=INDEX(_xlfn.TEXTSPLIT(A7, " "), 4)} -> crypto-server-default-clientssl
A8: ltm profile client-ssl clientssl-secure { | B8: =MID(A8,FIND("ltm profile ",A8)+12,FIND(" ",A8,FIND("ltm profile ",A8)+12)-FIND("ltm profile ",A8)-12) -> client-ssl | C8: {=INDEX(_xlfn.TEXTSPLIT(A8, " "), 4)} -> clientssl-secure
A9: ltm profile client-ssl splitsession-default-clientssl { | B9: =MID(A9,FIND("ltm profile ",A9)+12,FIND(" ",A9,FIND("ltm profile ",A9)+12)-FIND("ltm profile ",A9)-12) -> client-ssl | C9: {=INDEX(_xlfn.TEXTSPLIT(A9, " "), 4)} -> splitsession-default-clientssl
A10: ltm profile client-ssl clientssl-quic { | B10: =MID(A10,FIND("ltm profile ",A10)+12,FIND(" ",A10,FIND("ltm profile ",A10)+12)-FIND("ltm profile ",A10)-12) -> client-ssl | C10: {=INDEX(_xlfn.TEXTSPLIT(A10, " "), 4)} -> clientssl-quic
A11: ltm profile client-ssl s3-default-clientssl { | B11: =MID(A11,FIND("ltm profile ",A11)+12,FIND(" ",A11,FIND("ltm profile ",A11)+12)-FIND("ltm profile ",A11)-12) -> client-ssl | C11: {=INDEX(_xlfn.TEXTSPLIT(A11, " "), 4)} -> s3-default-clientssl
A12: ltm profile server-ssl splitsession-default-serverssl { | B12: =MID(A12,FIND("ltm profile ",A12)+12,FIND(" ",A12,FIND("ltm profile ",A12)+12)-FIND("ltm profile ",A12)-12) -> server-ssl | C12: {=INDEX(_xlfn.TEXTSPLIT(A12, " "), 4)} -> splitsession-default-serverssl
A13: ltm profile server-ssl cloud-service-default-ssl { | B13: =MID(A13,FIND("ltm profile ",A13)+12,FIND(" ",A13,FIND("ltm profile ",A13)+12)-FIND("ltm profile ",A13)-12) -> server-ssl | C13: {=INDEX(_xlfn.TEXTSPLIT(A13, " "), 4)} -> cloud-service-default-ssl
... A132: ltm profile json json { | B132: =MID(A132,FIND("ltm profile ",A132)+12,FIND(" ",A132,FIND("ltm profile ",A132)+12)-FIND("ltm profile ",A132)-12) -> json | C132: {=INDEX(_xlfn.TEXTSPLIT(A132, " "), 4)} -> json

Sheet ltmprofile
A1: PASTE ONE LINE CONFIG HERE | B1: NAME | C1: PROFILE
B2: {=_xlfn.IFS(C2="client-ssl",MID(A2,FIND("/",A2),FIND(" ",A2,FIND("/",A2))-FIND("/",A2))&" { context clientside }",C2="server-ssl",MID(A2,FIND("/",A2),FIND(" ",A2,FIND("/",A2))-FIND("/",A2))&" { context serverside }",TRUE,MID(A2,FIND("/",A2),FIND(" ",A2,FIND("/",A2))-FIND("/",A2)))} -> #VALUE! | C2: =MID(MID(A2,FIND("profile ",A2)+8,100),1,FIND(" ",MID(A2,FIND("profile ",A2)+8,100))-1) -> #VALUE!

Sheet ltmmonitor
A1: PASTE ONE LINE CONFIG HERE | B1: PARTITION | C1: MONITOR NAME | D1: TYPE | E1: SEND STRING | F1: RECEIVE STRING
B2: =MID(MID(A2,FIND("/",A2),100),1,FIND("/",MID(A2,FIND("/",A2),100),2)) -> #VALUE! | C2: =MID(A2,FIND("/",A2),FIND(" ",A2,FIND("/",A2))-FIND("/",A2)) -> #VALUE! | D2: =MID(A2,FIND("monitor ",A2)+8,FIND(" ",A2,FIND("monitor ",A2)+8)-FIND("monitor ",A2)-8) -> #VALUE! | E2: =IF(OR(D2="http",D2="https"),MID(MID(A2,FIND(" send ",A2)+7,1000),1,FIND("""",MID(A2,FIND(" send ",A2)+7,1000))-1),"") -> #VALUE! | F2: =IF(OR(D2="http",D2="https"),MID(SUBSTITUTE(SUBSTITUTE(A2," recv ","@")," recv-disable ","#"),FIND("@",SUBSTITUTE(SUBSTITUTE(A2," recv ","@")," recv-disable ","#") )+1,FIND("#",SUBSTITUTE(SUBSTITUTE(A2," recv ","@")," recv-disable ","#") )-FIND("@",SUBSTITUTE(SUBSTITUTE(A2," recv ","@")," recv-disable ","#") )-1),"") -> #VALUE!

Sheet ltmnode
A1: PASTE ONE LINE CONFIG HERE | B1: Replace last } with " }" | C1: NDOE NAME | D1: ADDRESS
B2: =LEFT(A2,LEN(A2)-1)&" }" -> #VALUE! | C2: =MID(A2,FIND("node /",A2)+5,FIND(" ",A2,FIND("node /",A2)+5)-FIND("node /",A2)-5) -> #VALUE! | D2: =MID(B2,FIND("address ",B2)+8,FIND(" ",B2,FIND("address ",B2)+8)-FIND("address ",B2)-8) -> #VALUE!

Sheet ltmpool
A1: PASTE ONE LINE CONFIG HERE | B1: Replace last } with " }" | C1: POOL NAME | D1: LOAD BALANCING MODE | E1: MONITOR | F1: Column1 | G1: POOL MEMBERS | H1: POOL MEMBER COUNT | I1: 1 | J1: 3 | K1: 5 | L1: 7 | M1: 9 | N1: 11 | O1: 13 | P1: 15 | Q1: 17 | R1: 19
B2: =LEFT(A2,LEN(A2)-1)&" }" -> #VALUE! | C2: =MID(A2,FIND("pool /",A2)+5,FIND(" ",A2,FIND("pool /",A2)+5)-FIND("pool /",A2)-5) -> #VALUE! | D2: =IFERROR(MID(A2,FIND("load-balancing-mode ",A2)+20,FIND(" ",A2,FIND("load-balancing-mode ",A2)+20)-FIND("load-balancing-mode ",A2)-20),"round-robin") -> round-robin | E2: =IF(MID(B2,FIND("monitor ",B2)+8,FIND(" ",B2,FIND("monitor ",B2)+8)-FIND("monitor ",B2)-8)="min",MID(A2,FIND("monitor ",A2)+8,FIND(" }",A2,FIND("monitor ",A2)+8)-FIND("monitor ",A2)-6),MID(B2,FIND("monitor ",B2)+8,FIND(" ",B2,FIND("monitor ",B2)+8)-FIND("monitor ",B2)-8)) -> #VALUE! | F2: =FIND("monitor min",A2) -> #VALUE! | G2: =MID(A2,FIND("members ",A2)+10,FIND("} }",A2,FIND("members ",A2)+10)-FIND("members ",A2)-8) -> #VALUE! | H2: =(LEN(G2)-LEN(SUBSTITUTE(G2,":",""))) -> #VALUE! | I2: =IFERROR(MID(SUBSTITUTE($G2,"/","@/",I$1),FIND("@/",SUBSTITUTE($G2,"/","@/",I$1))+1,FIND("}",SUBSTITUTE($G2,"/","@/",I$1),FIND("@/",SUBSTITUTE($G2,"/","@/",I$1)))-FIND("@/",SUBSTITUTE($G2,"/","@/",I$1))),"") | J2: =IFERROR(MID(SUBSTITUTE($G2,"/","@/",J$1),FIND("@/",SUBSTITUTE($G2,"/","@/",J$1))+1,FIND("}",SUBSTITUTE($G2,"/","@/",J$1),FIND("@/",SUBSTITUTE($G2,"/","@/",J$1)))-FIND("@/",SUBSTITUTE($G2,"/","@/",J$1))),"") | K2: =IFERROR(MID(SUBSTITUTE($G2,"/","@/",K$1),FIND("@/",SUBSTITUTE($G2,"/","@/",K$1))+1,FIND("}",SUBSTITUTE($G2,"/","@/",K$1),FIND("@/",SUBSTITUTE($G2,"/","@/",K$1)))-FIND("@/",SUBSTITUTE($G2,"/","@/",K$1))),"") | L2: =IFERROR(MID(SUBSTITUTE($G2,"/","@/",L$1),FIND("@/",SUBSTITUTE($G2,"/","@/",L$1))+1,FIND("}",SUBSTITUTE($G2,"/","@/",L$1),FIND("@/",SUBSTITUTE($G2,"/","@/",L$1)))-FIND("@/",SUBSTITUTE($G2,"/","@/",L$1))),"") | M2: =IFERROR(MID(SUBSTITUTE($G2,"/","@/",M$1),FIND("@/",SUBSTITUTE($G2,"/","@/",M$1))+1,FIND("}",SUBSTITUTE($G2,"/","@/",M$1),FIND("@/",SUBSTITUTE($G2,"/","@/",M$1)))-FIND("@/",SUBSTITUTE($G2,"/","@/",M$1))),"") | N2: =IFERROR(MID(SUBSTITUTE($G2,"/","@/",N$1),FIND("@/",SUBSTITUTE($G2,"/","@/",N$1))+1,FIND("}",SUBSTITUTE($G2,"/","@/",N$1),FIND("@/",SUBSTITUTE($G2,"/","@/",N$1)))-FIND("@/",SUBSTITUTE($G2,"/","@/",N$1))),"") | O2: =IFERROR(MID(SUBSTITUTE($G2,"/","@/",O$1),FIND("@/",SUBSTITUTE($G2,"/","@/",O$1))+1,FIND("}",SUBSTITUTE($G2,"/","@/",O$1),FIND("@/",SUBSTITUTE($G2,"/","@/",O$1)))-FIND("@/",SUBSTITUTE($G2,"/","@/",O$1))),"") | P2: =IFERROR(MID(SUBSTITUTE($G2,"/","@/",P$1),FIND("@/",SUBSTITUTE($G2,"/","@/",P$1))+1,FIND("}",SUBSTITUTE($G2,"/","@/",P$1),FIND("@/",SUBSTITUTE($G2,"/","@/",P$1)))-FIND("@/",SUBSTITUTE($G2,"/","@/",P$1))),"") | ... R2: =IFERROR(MID(SUBSTITUTE($G2,"/","@/",R$1),FIND("@/",SUBSTITUTE($G2,"/","@/",R$1))+1,FIND("}",SUBSTITUTE($G2,"/","@/",R$1),FIND("@/",SUBSTITUTE($G2,"/","@/",R$1)))-FIND("@/",SUBSTITUTE($G2,"/","@/",R$1))),"")

Sheet ltmpolicy
A1: PASTE ONE LINE CONFIG HERE | B1: NAME
B2: =MID(A2,FIND("policy ",A2)+7,FIND(" ",A2,FIND("policy ",A2)+7)-FIND("policy ",A2)-7) -> #VALUE!

Sheet ltmsnatpool
A1: PASTE ONE LINE CONFIG HERE | B1: Replace last } with " }" | C1: SNATPOOL NAME | D1: POOL MEMBERS | E1: POOL MEMBER COUNT | F1: 1 | G1: 3 | H1: 5 | I1: 7 | J1: 9 | K1: 11 | L1: 13 | M1: 15 | N1: 17 | O1: 19
B2: =LEFT(A2,LEN(A2)-1)&" }" -> #VALUE! | C2: =MID(A2,FIND("pool /",A2)+5,FIND(" ",A2,FIND("pool /",A2)+5)-FIND("pool /",A2)-5) -> #VALUE! | D2: =MID(B2,FIND("members ",B2)+10,FIND("} }",B2,FIND("members ",B2)+10)-FIND("members ",B2)-8) -> #VALUE! | E2: =(LEN(D2)-LEN(SUBSTITUTE(D2,".","")))/3 -> #VALUE! | F2: =IFERROR(MID(SUBSTITUTE($D2,"/","@/",F$1),FIND("@/",SUBSTITUTE($D2,"/","@/",F$1))+1,FIND("}",SUBSTITUTE($D2,"/","@/",F$1),FIND("@/",SUBSTITUTE($D2,"/","@/",F$1)))-FIND("@/",SUBSTITUTE($D2,"/","@/",F$1))),"") | G2: =IFERROR(MID(SUBSTITUTE($D2,"/","@/",G$1),FIND("@/",SUBSTITUTE($D2,"/","@/",G$1))+1,FIND("}",SUBSTITUTE($D2,"/","@/",G$1),FIND("@/",SUBSTITUTE($D2,"/","@/",G$1)))-FIND("@/",SUBSTITUTE($D2,"/","@/",G$1))),"") | H2: =IFERROR(MID(SUBSTITUTE($D2,"/","@/",H$1),FIND("@/",SUBSTITUTE($D2,"/","@/",H$1))+1,FIND("}",SUBSTITUTE($D2,"/","@/",H$1),FIND("@/",SUBSTITUTE($D2,"/","@/",H$1)))-FIND("@/",SUBSTITUTE($D2,"/","@/",H$1))),"") | I2: =IFERROR(MID(SUBSTITUTE($D2,"/","@/",I$1),FIND("@/",SUBSTITUTE($D2,"/","@/",I$1))+1,FIND("}",SUBSTITUTE($D2,"/","@/",I$1),FIND("@/",SUBSTITUTE($D2,"/","@/",I$1)))-FIND("@/",SUBSTITUTE($D2,"/","@/",I$1))),"") | J2: =IFERROR(MID(SUBSTITUTE($D2,"/","@/",J$1),FIND("@/",SUBSTITUTE($D2,"/","@/",J$1))+1,FIND("}",SUBSTITUTE($D2,"/","@/",J$1),FIND("@/",SUBSTITUTE($D2,"/","@/",J$1)))-FIND("@/",SUBSTITUTE($D2,"/","@/",J$1))),"") | K2: =IFERROR(MID(SUBSTITUTE($D2,"/","@/",K$1),FIND("@/",SUBSTITUTE($D2,"/","@/",K$1))+1,FIND("}",SUBSTITUTE($D2,"/","@/",K$1),FIND("@/",SUBSTITUTE($D2,"/","@/",K$1)))-FIND("@/",SUBSTITUTE($D2,"/","@/",K$1))),"") | L2: =IFERROR(MID(SUBSTITUTE($D2,"/","@/",L$1),FIND("@/",SUBSTITUTE($D2,"/","@/",L$1))+1,FIND("}",SUBSTITUTE($D2,"/","@/",L$1),FIND("@/",SUBSTITUTE($D2,"/","@/",L$1)))-FIND("@/",SUBSTITUTE($D2,"/","@/",L$1))),"") | M2: =IFERROR(MID(SUBSTITUTE($D2,"/","@/",M$1),FIND("@/",SUBSTITUTE($D2,"/","@/",M$1))+1,FIND("}",SUBSTITUTE($D2,"/","@/",M$1),FIND("@/",SUBSTITUTE($D2,"/","@/",M$1)))-FIND("@/",SUBSTITUTE($D2,"/","@/",M$1))),"") | ... O2: =IFERROR(MID(SUBSTITUTE($D2,"/","@/",O$1),FIND("@/",SUBSTITUTE($D2,"/","@/",O$1))+1,FIND("}",SUBSTITUTE($D2,"/","@/",O$1),FIND("@/",SUBSTITUTE($D2,"/","@/",O$1)))-FIND("@/",SUBSTITUTE($D2,"/","@/",O$1))),"")

Sheet ltmcipherrule
A1: PASTE ONE LINE CONFIG HERE | B1: Replace last } with " }" | C1: NAME
B2: =LEFT(A2,LEN(A2)-1)&" }" -> #VALUE! | C2: =MID(A2,FIND("/",A2),FIND(" ",A2,FIND("/",A2))-FIND("/",A2)) -> #VALUE!

Sheet ltmciphergroup
A1: PASTE ONE LINE CONFIG HERE | B1: Replace last } with " }" | C1: NAME
B2: =LEFT(A2,LEN(A2)-1)&" }" -> #VALUE! | C2: =MID(A2,FIND("/",A2),FIND(" ",A2,FIND("/",A2))-FIND("/",A2)) -> #VALUE!

Sheet ltmclientssl
A1: PASTE ONE LINE CONFIG HERE | B1: Replace last } with " }" | C1: NAME | D1: PROFILE | E1: CERT | F1: KEY | G1: CERT CACHE PATH | H1: REMOVE FILE STORE PATH | I1: SUBJECT | J1: SAN | K1: KEY CACHE PATH | L1: CIPHERS | M1: CIPHER GROUP
B2: =LEFT(A2,LEN(A2)-1)&" }" -> #VALUE! | C2: =MID(A2,FIND("/",A2),FIND(" ",A2,FIND("/",A2))-FIND("/",A2)) -> #VALUE! | D2: =MID(A2,FIND("client-ssl ",A2),FIND(" ",A2,FIND("client-ssl ",A2))-FIND("client-ssl ",A2)) -> #VALUE! | E2: =MID(A2,FIND("cert /",A2)+5,FIND(" ",A2,FIND("cert /",A2)+5)-FIND("cert /",A2)-5) -> #VALUE! | F2: =MID(B2,FIND("key /",B2)+4,FIND(" ",B2,FIND("key /",B2)+4)-FIND("key /",B2)-4) -> #VALUE! | G2: =VLOOKUP(ClientSSL[[#This Row],[CERT]],Cert[[#All],[NAME]:[CACHE PATH]],2,FALSE) -> #VALUE! | H2: =SUBSTITUTE(SUBSTITUTE(ClientSSL[[#This Row],[CERT CACHE PATH]],"/config/filestore/files_d/Common_d/certificate_d/",""),":","_") -> #VALUE! | I2: =_xlfn.XLOOKUP(ClientSSL[[#This Row],[REMOVE FILE STORE PATH]],CertificateDetails[FileName],CertificateDetails[Subject]) -> #VALUE! | J2: =_xlfn.XLOOKUP(ClientSSL[[#This Row],[REMOVE FILE STORE PATH]],CertificateDetails[FileName],CertificateDetails[SAN without CHAR(10)]) -> #VALUE! | L2: =MID(A2,FIND("ciphers ",A2)+8,FIND(" ",A2,FIND("ciphers ",A2)+8)-FIND("ciphers ",A2)-8) -> #VALUE! | M2: =MID(A2,FIND("cipher-group ",A2)+13,FIND(" ",A2,FIND("cipher-group ",A2)+13)-FIND("cipher-group ",A2)-13) -> #VALUE!

Sheet ltmserverssl
A1: PASTE ONE LINE CONFIG HERE | B1: Replace last } with " }" | C1: NAME | D1: PROFILE | E1: CERT | F1: KEY | G1: CERT CACHE PATH | H1: REMOVE FILE STORE PATH | I1: SUBJECT | J1: SAN | K1: KEY CACHE PATH | L1: CIPHERS | M1: CIPHER GROUP
B2: =LEFT(A2,LEN(A2)-1)&" }" -> #VALUE! | C2: =MID(A2,FIND("/",A2),FIND(" ",A2,FIND("/",A2))-FIND("/",A2)) -> #VALUE! | D2: =MID(A2,FIND("client-ssl ",A2),FIND(" ",A2,FIND("client-ssl ",A2))-FIND("client-ssl ",A2)) -> #VALUE! | E2: =MID(A2,FIND("cert /",A2)+5,FIND(" ",A2,FIND("cert /",A2)+5)-FIND("cert /",A2)-5) -> #VALUE! | F2: =MID(B2,FIND("key /",B2)+4,FIND(" ",B2,FIND("key /",B2)+4)-FIND("key /",B2)-4) -> #VALUE! | G2: =VLOOKUP(ServerSSL[[#This Row],[CERT]],Cert[[#All],[NAME]:[CACHE PATH]],2,FALSE) -> #VALUE! | H2: =SUBSTITUTE(SUBSTITUTE(ServerSSL[[#This Row],[CERT CACHE PATH]],"/config/filestore/files_d/Common_d/certificate_d/",""),":","_") -> #VALUE! | I2: =_xlfn.XLOOKUP(ServerSSL[[#This Row],[REMOVE FILE STORE PATH]],CertificateDetails[FileName],CertificateDetails[Subject]) -> #VALUE! | J2: =_xlfn.XLOOKUP(ServerSSL[[#This Row],[REMOVE FILE STORE PATH]],CertificateDetails[FileName],CertificateDetails[SAN]) -> #VALUE! | L2: =MID(A2,FIND("ciphers ",A2)+8,FIND(" ",A2,FIND("ciphers ",A2)+8)-FIND("ciphers ",A2)-8) -> #VALUE! | M2: =MID(A2,FIND("cipher-group ",A2)+13,FIND(" ",A2,FIND("cipher-group ",A2)+13)-FIND("cipher-group ",A2)-13) -> #VALUE!

Sheet ltmvirtualserver
A1: PASTE ONE LINE CONFIG HERE | B1: PARTITION | C1: VS NAME | D1: DESCRIPTION | E1: LAST MODIFIED TIME | F1: SOURCE IP | G1: VS IP TYPE | H1: VS IP PORT | I1: VS IP | J1: VS PORT | K1: IP FORWARD PROFILE | L1: FASTL4 PROFILE | M1: PROTOCOL | N1: TCP PROFILE | O1: UDP PROFILE | P1: HTTP PROFILE | Q1: ASM PROFILE | R1: POLICIES | S1: SSL TRAFFIC | T1: CLIENT SSL PROFILE | U1: CN & SAN | V1: SERVER SSL PROFILE | W1: SNAT | X1: SNAT (<v11.6) | Y1: PERSIST | Z1: FALLBACK PERSIST | AA1: IRULE | AB1: MONITOR | AC1: SEND STRING (NO FORMULA YET) | AD1: RECEIVE STRING (NO FORMULA YET) | AE1: LOAD BALANCING MODE | AF1: POOL | AG1: POOL MEMBER | AH1: IRULE COUNT | AI1: ALL PROFILES | AJ1: COUNT PROFILE / DIVIDE BY 2 | AK1: 1 | AL1: 2 | AM1: 3 | AN1: 4 | AO1: 5 | AP1: 6 | AQ1: 7 | AR1: 8 | AS1: 9 | AT1: 10 | AU1: PROFILE TYPE 1 | AV1: PROFILE TYPE 2 | AW1: PROFILE TYPE 3 | AX1: PROFILE TYPE 4 | AY1: PROFILE TYPE 5 | AZ1: PROFILE TYPE 6 | BA1: PROFILE TYPE 7 | BB1: PROFILE TYPE 8 | BC1: PROFILE TYPE 9 | BD1: PROFILE TYPE 10
B2: =MID(MID(A2,FIND("/",A2),100),1,FIND("/",MID(A2,FIND("/",A2),100),2)) -> #VALUE! | C2: =MID(MID(SUBSTITUTE(A2,"/","@",2),FIND("@",SUBSTITUTE(A2,"/","@",2))+1,1000),1,FIND(" ",MID(SUBSTITUTE(A2,"/","@",2),FIND("@",SUBSTITUTE(A2,"/","@",2))+1,1000))-1) -> #VALUE! | D2: =IFERROR(MID(MID(A2,FIND("description",A2)+12,1000),1,FIND("destination",MID(A2,FIND("description",A2)+12,1000))-1),"") | E2: =IFERROR(MID(A2,FIND(" last-modified-time ",A2)+20,FIND(" ",A2,FIND(" last-modified-time ",A2)+20)-FIND(" last-modified-time ",A2)-20),"") | F2: =IFERROR(MID(A2,FIND(" source ",A2)+8,FIND(" ",A2,FIND(" source ",A2)+8)-FIND(" source ",A2)-8),"") | G2: =IF(LEN(H2)-LEN(SUBSTITUTE(H2,":",""))=1,"IPv4","IPv6") -> IPv6 | H2: =IFERROR(MID(A2,FIND(" destination ",A2)+13,FIND(" ",A2,FIND(" destination ",A2)+13)-FIND(" destination ",A2)-13),"") | I2: =IF(G2="IPv4",LEFT(H2,FIND(":",H2)-1),LEFT(H2,FIND(".",H2)-1)) -> #VALUE! | J2: =IF(G2="IPv4",RIGHT(H2,LEN(H2)-FIND(":",H2)),RIGHT(H2,LEN(H2)-FIND(".",H2))) -> #VALUE! | K2: =IFERROR(MID(A2,FIND("ip-forward",A2),10),"") | L2: =IFERROR(MID(MID(AI2,FIND("fastL4",AI2),100),1,FIND("{ }",MID(AI2,FIND("fastL4",AI2),100))-2),"") | M2: =IFERROR(MID(MID(MID(A2,FIND("ip-protocol",A2),50),FIND(" ",MID(A2,FIND("ip-protocol",A2),50))+1,10),1,FIND(" ",MID(MID(A2,FIND("ip-protocol",A2),50),FIND(" ",MID(A2,FIND("ip-protocol",A2),50))+1,10))-1),"") | N2: =IF(AU2="tcp",AK2,IF(AV2="tcp",AL2,IF(AW2="tcp",AM2,IF(AX2="tcp",AN2,IF(AY2="tcp",AO2,IF(AZ2="tcp",AP2,IF(BA2="tcp",AQ2,IF(BB2="tcp",AR2,IF(BC2="tcp",AS2,IF(BD2="tcp",AT2,"")))))))))) | O2: =IF(AU2="udp",AK2,IF(AV2="udp",AL2,IF(AW2="udp",AM2,IF(AX2="udp",AN2,IF(AY2="udp",AO2,IF(AZ2="udp",AP2,IF(BA2="udp",AQ2,IF(BB2="udp",AR2,IF(BC2="udp",AS2,IF(BD2="udp",AT2,"")))))))))) | P2: =IF(AU2="http",AK2,IF(AV2="http",AL2,IF(AW2="http",AM2,IF(AX2="http",AN2,IF(AY2="http",AO2,IF(AZ2="http",AP2,IF(BA2="http",AQ2,IF(BB2="http",AR2,IF(BC2="http",AS2,IF(BD2="http",AT2,"")))))))))) | Q2: =IF(AU2="asm",AK2,IF(AV2="asm",AL2,IF(AW2="asm",AM2,IF(AX2="asm",AN2,IF(AY2="asm",AO2,IF(AZ2="asm",AP2,IF(BA2="asm",AQ2,IF(BB2="asm",AR2,IF(BC2="asm",AS2,IF(BD2="asm",AT2,"")))))))))) | R2: =IFERROR(MID(A2,FIND(" policies ",A2)+12,FIND("} )",A2,FIND(" policies ",A2)+12)-FIND(" policies ",A2)-12),"") | T2: =IF(AU2="client-ssl",AK2&" ","")&IF(AV2="client-ssl",AL2&" ","")&IF(AW2="client-ssl",AM2&" ","")&IF(AX2="client-ssl",AN2&" ","")&IF(AY2="client-ssl",AO2&" ","")&IF(AZ2="client-ssl",AP2&" ","")&IF(BA2="client-ssl",AQ2&" ","")&IF(BB2="client-ssl",AR2&" ","")&IF(BC2="client-ssl",AS2&" ","")&IF(BD2="client-ssl",AT2&" ","") | U2: {=SUBSTITUTE(IF(AT2="client-ssl",_xlfn.XLOOKUP(SUBSTITUTE(AJ2," { context clientside }",""),ClientSSL[NAME],"CN:"&ClientSSL[NAME]&" SAN:"&ClientSSL[SAN]&" ","",0),"")&IF(AU2="client-ssl",_xlfn.XLOOKUP(SUBSTITUTE(AK2," { context clientside }",""),ClientSSL[NAME],"CN:"&ClientSSL[NAME]&" SAN:"&ClientSSL[SAN]&" ","",0),"")&IF(AV2="client-ssl",_xlfn.XLOOKUP(SUBSTITUTE(AL2," { context clientside }",""),ClientSSL[NAME],"CN:"&ClientSSL[NAME]&" SAN:"&ClientSSL[SAN]&" ","",0),"") &IF(AW2="client-ssl",_xlfn.XLOOKUP(SUBSTITUTE(AM2," { context clientside }",""),ClientSSL[NAME],"CN:"&ClientSSL[NAME]&" SAN:"&ClientSSL[SAN]&" ","",0),"")&IF(AX2="client-ssl",_xlfn.XLOOKUP(SUBSTITUTE(AN2," { context clientside }",""),ClientSSL[NAME],"CN:"&ClientSSL[NAME]&" SAN:"&ClientSSL[SAN]&" ","",0),"")&IF(AY2="client-ssl",_xlfn.XLOOKUP(SUBSTITUTE(AO2," { context clientside }",""),ClientSSL[NAME],"CN:"&ClientSSL[NAME]&" SAN:"&ClientSSL[SAN]&" ","",0),"") &IF(AZ2="client-ssl",_xlfn.XLOOKUP(SUBSTITUTE(AP2," { context clientside }",""),ClientSSL[NAME],"CN:"&ClientSSL[NAME]&" SAN:"&ClientSSL[SAN]&" ","",0),"")&IF(BA2="client-ssl",_xlfn.XLOOKUP(SUBSTITUTE(AQ2," { context clientside }",""),ClientSSL[NAME],"CN:"&ClientSSL[NAME]&" SAN:"&ClientSSL[SAN]&" ","",0),"")&IF(BB2="client-ssl",_xlfn.XLOOKUP(SUBSTITUTE(AR2," { context clientside }",""),ClientSSL[NAME],"CN:"&ClientSSL[NAME]&" SAN:"&ClientSSL[SAN]&" ","",0),"") &IF(BC2="client-ssl",_xlfn.XLOOKUP(SUBSTITUTE(AS2," { context clientside }",""),ClientSSL[NAME],"CN:"&ClientSSL[NAME]&" SAN:"&ClientSSL[SAN]&" ","",0),"")," CN:",CHAR(10)&"CN:")} | V2: =IF(AU2="server-ssl",AK2,IF(AV2="server-ssl",AL2,IF(AW2="server-ssl",AM2,IF(AX2="server-ssl",AN2,IF(AY2="server-ssl",AO2,IF(AZ2="server-ssl",AP2,IF(BA2="server-ssl",AQ2,IF(BB2="server-ssl",AR2,IF(BC2="server-ssl",AS2,IF(BD2="server-ssl",AT2,"")))))))))) | W2: =MID(A2,FIND("source-address-translation { ",A2)+29,FIND(" }",A2,FIND("source-address-translation { ",A2)+29)-FIND("source-address-translation { ",A2)-29) -> #VALUE! | X2: =IFERROR(MID(A2,FIND("snat ",A2)+5,FIND(" ",A2,FIND("snat ",A2)+5)-FIND("snat ",A2)-5),"") | Y2: =IFERROR(MID(MID(MID(MID(A2,FIND("persist",A2),50),FIND("{",MID(A2,FIND("persist",A2),50))+1,100),FIND("n/",MID(MID(A2,FIND("persist",A2),50),FIND("{",MID(A2,FIND("persist",A2),50))+1,100))+2,50),1,FIND(" ",MID(MID(MID(A2,FIND("persist",A2),50),FIND("{",MID(A2,FIND("persist",A2),50))+1,100),FIND("n/",MID(MID(A2,FIND("persist",A2),50),FIND("{",MID(A2,FIND("persist",A2),50))+1,100))+2,50))-1),"") | Z2: =IFERROR(MID(MID(MID(A2,FIND("fallback-persistence",A2),50),FIND("n/",MID(A2,FIND("fallback-persistence",A2),50))+2,50),1,FIND(" ",MID(MID(A2,FIND("fallback-persistence",A2),50),FIND("n/",MID(A2,FIND("fallback-persistence",A2),50))+2,50))-1),"") | AA2: =IFERROR(MID(MID(A2,FIND("rules {",A2)+8,10000),1,FIND("}",MID(A2,FIND("rules {",A2)+8,10000))-2),"") | AB2: =IFERROR(SUBSTITUTE(VLOOKUP(AF2,ltmpool!C:G,3,FALSE),"}","}"&CHAR(10)),"") | AE2: =IFERROR(SUBSTITUTE(VLOOKUP(AF2,ltmpool!C:G,2,FALSE),"}","}"&CHAR(10)),"") | AF2: =IFERROR(MID(A2,FIND("pool /",A2)+5,FIND(" ",A2,FIND("pool /",A2)+5)-FIND("pool /",A2)-5),"") | AG2: =IFERROR(SUBSTITUTE(VLOOKUP(AF2,ltmpool!C:H,5,FALSE),"} /","} "&CHAR(10)&"/"),"") | AH2: =(LEN(AA2)-LEN(SUBSTITUTE(AA2,"/","")))/2 -> 0 | AI2: =MID(MID(A2,FIND("profiles { /",A2)+11,2000),1,FIND("} }",MID(A2,FIND("profiles { /",A2)+11,2000))+1) -> #VALUE! | AJ2: =(LEN(AI2)-LEN(SUBSTITUTE(AI2,"}",""))) -> #VALUE! | AK2: =SUBSTITUTE(LEFT(SUBSTITUTE(AI2," }"," @",1),FIND("@",SUBSTITUTE(AI2," }"," @",1))),"@","}") -> #VALUE! | AL2: =IFERROR(MID(AI2,FIND("@",SUBSTITUTE(AI2," }","@",1))+3,FIND("#",SUBSTITUTE(AI2," }","#",2))-FIND("@",SUBSTITUTE(AI2," }","@",1))-1),"") | AM2: =IFERROR(MID(AI2,FIND("@",SUBSTITUTE(AI2," }","@",2))+3,FIND("#",SUBSTITUTE(AI2," }","#",3))-FIND("@",SUBSTITUTE(AI2," }","@",2))-1),"") | AN2: =IFERROR(MID(AI2,FIND("@",SUBSTITUTE(AI2," }","@",3))+3,FIND("#",SUBSTITUTE(AI2," }","#",4))-FIND("@",SUBSTITUTE(AI2," }","@",3))-1),"") | AO2: =IFERROR(MID(AI2,FIND("@",SUBSTITUTE(AI2," }","@",4))+3,FIND("#",SUBSTITUTE(AI2," }","#",5))-FIND("@",SUBSTITUTE(AI2," }","@",4))-1),"") | AP2: =IFERROR(MID(AI2,FIND("@",SUBSTITUTE(AI2," }","@",5))+3,FIND("#",SUBSTITUTE(AI2," }","#",6))-FIND("@",SUBSTITUTE(AI2," }","@",5))-1),"") | AQ2: =IFERROR(MID(AI2,FIND("@",SUBSTITUTE(AI2," }","@",6))+3,FIND("#",SUBSTITUTE(AI2," }","#",7))-FIND("@",SUBSTITUTE(AI2," }","@",6))-1),"") | AR2: =IFERROR(MID(AI2,FIND("@",SUBSTITUTE(AI2," }","@",7))+3,FIND("#",SUBSTITUTE(AI2," }","#",8))-FIND("@",SUBSTITUTE(AI2," }","@",7))-1),"") | AS2: =IFERROR(MID(AI2,FIND("@",SUBSTITUTE(AI2," }","@",8))+3,FIND("#",SUBSTITUTE(AI2," }","#",9))-FIND("@",SUBSTITUTE(AI2," }","@",8))-1),"") | AT2: =IFERROR(MID(AI2,FIND("@",SUBSTITUTE(AI2," }","@",9))+3,FIND("#",SUBSTITUTE(AI2," }","#",10))-FIND("@",SUBSTITUTE(AI2," }","@",9))-1),"") | AU2: =IFERROR(IFERROR(IFERROR(VLOOKUP(SUBSTITUTE(AK2," { }",""),ltmprofile!$B:$C,2,FALSE),VLOOKUP(SUBSTITUTE(AK2," { }",""),DefaultProfile[#All],2,FALSE)),VLOOKUP(SUBSTITUTE(AK2," { }",""),ASM[[POLICY NAME WITH ASM PREFIX]:[PROFILE TYPE]],2,FALSE)),"") | AV2: =IFERROR(IFERROR(IFERROR(VLOOKUP(SUBSTITUTE(AL2," { }",""),ltmprofile!$B:$C,2,FALSE),VLOOKUP(SUBSTITUTE(AL2," { }",""),DefaultProfile[#All],2,FALSE)),VLOOKUP(SUBSTITUTE(AL2," { }",""),ASM[[POLICY NAME WITH ASM PREFIX]:[PROFILE TYPE]],2,FALSE)),"") | AW2: =IFERROR(IFERROR(IFERROR(VLOOKUP(SUBSTITUTE(AM2," { }",""),ltmprofile!$B:$C,2,FALSE),VLOOKUP(SUBSTITUTE(AM2," { }",""),DefaultProfile[#All],2,FALSE)),VLOOKUP(SUBSTITUTE(AM2," { }",""),ASM[[POLICY NAME WITH ASM PREFIX]:[PROFILE TYPE]],2,FALSE)),"") | AX2: =IFERROR(IFERROR(IFERROR(VLOOKUP(SUBSTITUTE(AN2," { }",""),ltmprofile!$B:$C,2,FALSE),VLOOKUP(SUBSTITUTE(AN2," { }",""),DefaultProfile[#All],2,FALSE)),VLOOKUP(SUBSTITUTE(AN2," { }",""),ASM[[POLICY NAME WITH ASM PREFIX]:[PROFILE TYPE]],2,FALSE)),"") | AY2: =IFERROR(IFERROR(IFERROR(VLOOKUP(SUBSTITUTE(AO2," { }",""),ltmprofile!$B:$C,2,FALSE),VLOOKUP(SUBSTITUTE(AO2," { }",""),DefaultProfile[#All],2,FALSE)),VLOOKUP(SUBSTITUTE(AO2," { }",""),ASM[[POLICY NAME WITH ASM PREFIX]:[PROFILE TYPE]],2,FALSE)),"") | AZ2: =IFERROR(IFERROR(IFERROR(VLOOKUP(SUBSTITUTE(AP2," { }",""),ltmprofile!$B:$C,2,FALSE),VLOOKUP(SUBSTITUTE(AP2," { }",""),DefaultProfile[#All],2,FALSE)),VLOOKUP(SUBSTITUTE(AP2," { }",""),ASM[[POLICY NAME WITH ASM PREFIX]:[PROFILE TYPE]],2,FALSE)),"") | BA2: =IFERROR(IFERROR(IFERROR(VLOOKUP(SUBSTITUTE(AQ2," { }",""),ltmprofile!$B:$C,2,FALSE),VLOOKUP(SUBSTITUTE(AQ2," { }",""),DefaultProfile[#All],2,FALSE)),VLOOKUP(SUBSTITUTE(AQ2," { }",""),ASM[[POLICY NAME WITH ASM PREFIX]:[PROFILE TYPE]],2,FALSE)),"") | BB2: =IFERROR(IFERROR(IFERROR(VLOOKUP(SUBSTITUTE(AR2," { }",""),ltmprofile!$B:$C,2,FALSE),VLOOKUP(SUBSTITUTE(AR2," { }",""),DefaultProfile[#All],2,FALSE)),VLOOKUP(SUBSTITUTE(AR2," { }",""),ASM[[POLICY NAME WITH ASM PREFIX]:[PROFILE TYPE]],2,FALSE)),"") | ... BD2: =IFERROR(IFERROR(IFERROR(VLOOKUP(SUBSTITUTE(AT2," { }",""),ltmprofile!$B:$C,2,FALSE),VLOOKUP(SUBSTITUTE(AT2," { }",""),DefaultProfile[#All],2,FALSE)),VLOOKUP(SUBSTITUTE(AT2," { }",""),ASM[[POLICY NAME WITH ASM PREFIX]:[PROFILE TYPE]],2,FALSE)),"")

Sheet ltmvirtualaddress
A1: PASTE ONE LINE CONFIG HERE | B1: Replace last } with " }" | C1: NAME | D1: { address | E1: arp | F1: icmp-echo | G1: mask | H1: traffic-group | I1: route-advertisement
B2: =LEFT(A2,LEN(A2)-1)&" }" -> #VALUE! | C2: =MID(A2,FIND("/",A2),FIND(" ",A2,FIND("/",A2))-FIND("/",A2)) -> #VALUE! | D2: =MID($B2,FIND(D$1,$B2)+LEN(D$1),FIND(" ",$B2,FIND(D$1,$B2)+LEN(D$1))-FIND(D$1,$B2)-LEN(D$1)) -> #VALUE! | E2: =MID($B2,FIND(E$1,$B2)+LEN(E$1),FIND(" ",$B2,FIND(E$1,$B2)+LEN(E$1))-FIND(E$1,$B2)-LEN(E$1)) -> #VALUE! | F2: =MID($B2,FIND(F$1,$B2)+LEN(F$1),FIND(" ",$B2,FIND(F$1,$B2)+LEN(F$1))-FIND(F$1,$B2)-LEN(F$1)) -> #VALUE! | G2: =MID($B2,FIND(G$1,$B2)+LEN(G$1),FIND(" ",$B2,FIND(G$1,$B2)+LEN(G$1))-FIND(G$1,$B2)-LEN(G$1)) -> #VALUE! | H2: =MID($B2,FIND(H$1,$B2)+LEN(H$1),FIND(" ",$B2,FIND(H$1,$B2)+LEN(H$1))-FIND(H$1,$B2)-LEN(H$1)) -> #VALUE! | I2: =MID($B2,FIND(I$1,$B2)+LEN(I$1),FIND(" ",$B2,FIND(I$1,$B2)+LEN(I$1))-FIND(I$1,$B2)-LEN(I$1)) -> #VALUE!

Sheet GTM>>>>>>>>>>>>>>>>>>>>>>>>>>>>

Sheet gtmcert
A1: FileName | B1: FilePath | C1: Subject | D1: Issuer | E1: Thumbprint | F1: NotBefore | G1: NotAfter | H1: SAN

Sheet big3dcert
A1: FileName | B1: FilePath | C1: Subject | D1: Issuer | E1: Thumbprint | F1: NotBefore | G1: NotAfter | H1: SAN

Sheet gtmdatacenter
A1: PASTE ONE LINE CONFIG HERE | B1: Substitute last } with " }" | C1: DATACENTER NAME
B2: =SUBSTITUTE(A2,"}"," }",LEN(A2)-(LEN(SUBSTITUTE(A2,"}","")))) -> #VALUE! | C2: =MID(A2,FIND("gtm datacenter ",A2)+15,FIND(" ",A2,FIND("gtm datacenter ",A2)+15)-FIND("gtm datacenter ",A2)-15) -> #VALUE!

Sheet gtmproberpool
A1: PASTE ONE LINE CONFIG HERE | B1: Substitute last } with " }" | C1: prober-pool | D1: POOL MEMBERS (WRAP TEXT TO VIEW MULTILINE) | E1: POOL MEMBER COUNT
B2: =SUBSTITUTE(A2,"}"," }",LEN(A2)-(LEN(SUBSTITUTE(A2,"}","")))) -> #VALUE! | C2: =MID($B2,FIND(C$1,$B2)+LEN(C$1),FIND(" ",$B2,FIND(C$1,$B2)+LEN(C$1))-FIND(C$1,$B2)-LEN(C$1)) -> #VALUE! | D2: =SUBSTITUTE(MID(A2,FIND(" members { ",A2)+11,FIND("} }",A2,FIND(" members { ",A2)+11)-FIND(" members { ",A2)-11),"} /","}"&CHAR(10)&"/") -> #VALUE! | E2: =LEN(D2)-LEN(SUBSTITUTE(D2,"order","orde")) -> #VALUE!

Sheet gtmregion
A1: PASTE ONE LINE CONFIG HERE | B1: Substitute last } with " }" | C1: region | D1: SUBNET (WRAP TEXT TO VIEW MULTILINE) | E1: SUBNET COUNT
B2: =SUBSTITUTE(A2,"}"," }",LEN(A2)-(LEN(SUBSTITUTE(A2,"}","")))) -> #VALUE! | C2: =MID($B2,FIND(C$1,$B2)+LEN(C$1)+1,FIND(CHAR(34),$B2,FIND(C$1,$B2)+LEN(C$1)+1)-FIND(C$1,$B2)-LEN(C$1)-1) -> #VALUE! | D2: =SUBSTITUTE(MID(A2,FIND(" region-members { ",A2)+18,FIND("} }",A2,FIND(" region-members { ",A2)+18)-FIND(" region-members { ",A2)-18),"} s","}"&CHAR(10)&"s") -> #VALUE! | E2: =LEN(D2)-LEN(SUBSTITUTE(D2,"subnet","subne")) -> #VALUE!

Sheet gtmserver
A1: PASTE ONE LINE CONFIG HERE | B1: Substitute last } with " }" | C1: SERVER NAME | D1: DATACENTER | E1: DEVICES | F1: MONITOR | G1: PRODUCT | H1: VIRTUAL SERVER DISCOVERY | I1: VIRTUAL SERVER (WRAP TEXT TO SEE LIST OF VS) | J1: Pool Member Count
B2: =SUBSTITUTE(A2,"}"," }",LEN(A2)-(LEN(SUBSTITUTE(A2,"}","")))) -> #VALUE! | C2: =MID(A2,FIND("gtm server ",A2)+11,FIND(" ",A2,FIND("gtm server ",A2)+11)-FIND("gtm server ",A2)-11) -> #VALUE! | D2: =MID(A2,FIND("datacenter ",A2)+11,FIND(" ",A2,FIND("datacenter ",A2)+11)-FIND("datacenter ",A2)-11) -> #VALUE! | E2: =MID(B2,FIND("devices { ",B2)+10,FIND(" } }",B2,FIND("devices { ",B2)+10)-FIND("devices { ",B2)-10) -> #VALUE! | F2: =MID(A2,FIND("monitor ",A2)+8,FIND(" ",A2,FIND("monitor ",A2)+8)-FIND("monitor ",A2)-8) -> #VALUE! | G2: =IFERROR(MID(B2,FIND("product ",B2)+8,FIND(" ",B2,FIND("product ",B2)+8)-FIND("product ",B2)-8),"") | H2: =IFERROR(MID(A2,FIND("virtual-server-discovery ",A2)+25,FIND(" ",A2,FIND("virtual-server-discovery ",A2)+25)-FIND("virtual-server-discovery ",A2)-25),"") | I2: =IFERROR(MID(A2,FIND("virtual-servers { ",A2)+18,FIND("} }}",A2,FIND("virtual-servers { ",A2)+18)-FIND("virtual-servers { ",A2)-18),"") | J2: =LEN(I2)-LEN(SUBSTITUTE(I2,"destination","destinatio")) -> 0

Sheet gtmtopology
A1: PASTE ONE LINE CONFIG HERE | B1: Substitute last } with " }" | C1: LDNS | D1: SERVER
B2: =SUBSTITUTE(A2,"}"," }",LEN(A2)-(LEN(SUBSTITUTE(A2,"}","")))) -> #VALUE! | C2: =MID(A2,FIND(" ldns: ",A2)+7,FIND(" server:",A2,FIND(" ldns: ",A2)+7)-FIND(" ldns: ",A2)-7) -> #VALUE! | D2: =MID(A2,FIND(" server: ",A2)+9,FIND("}",A2,FIND(" server: ",A2)+9)-FIND(" server: ",A2)-9) -> #VALUE!

Sheet gtmglobalsettings
A1: PASTE ONE LINE CONFIG HERE | B1: Substitute last } with " }" | C1: synchronization | D1: synchronization-group-name
B2: =SUBSTITUTE(A2,"}"," }",LEN(A2)-(LEN(SUBSTITUTE(A2,"}","")))) -> #VALUE! | C2: =MID($B2,FIND(C$1,$B2)+LEN(C$1),FIND(" ",$B2,FIND(C$1,$B2)+LEN(C$1))-FIND(C$1,$B2)-LEN(C$1)) -> #VALUE! | D2: =MID($B2,FIND(D$1,$B2)+LEN(D$1),FIND(" ",$B2,FIND(D$1,$B2)+LEN(D$1))-FIND(D$1,$B2)-LEN(D$1)) -> #VALUE!

Sheet gtmmonitor
A1: PASTE ONE LINE CONFIG HERE | B1: Substitute last } with " }" | C1: MONITOR TYPE | D1: MONITOR NAME | E1: CIPHERLIST | F1: COMPATIBILITY | G1: DEFAULTS FROM | H1: DESTINATION | I1: INTERVAL | J1: PROBE TIMEOUT | K1: RECEIVE | L1: SEND | M1: TIMEOUT
B2: =SUBSTITUTE(A2,"}"," }",LEN(A2)-(LEN(SUBSTITUTE(A2,"}","")))) -> #VALUE! | C2: =MID(A2,FIND("gtm monitor ",A2)+12,FIND(" ",A2,FIND("gtm monitor ",A2)+12)-FIND("gtm monitor ",A2)-12) -> #VALUE! | D2: =MID(A2,FIND(" https ",A2)+7,FIND(" ",A2,FIND(" https ",A2)+7)-FIND(" https ",A2)-7) -> #VALUE! | E2: =MID(A2,FIND(" cipherlist ",A2)+12,FIND(" ",A2,FIND(" cipherlist ",A2)+12)-FIND(" cipherlist ",A2)-12) -> #VALUE! | F2: =MID(A2,FIND(" compatibility ",A2)+15,FIND(" ",A2,FIND(" compatibility ",A2)+15)-FIND(" compatibility ",A2)-15) -> #VALUE! | G2: =MID(A2,FIND(" defaults-from ",A2)+15,FIND(" ",A2,FIND(" defaults-from ",A2)+15)-FIND(" defaults-from ",A2)-15) -> #VALUE! | H2: =MID(A2,FIND(" destination ",A2)+13,FIND(" ",A2,FIND(" destination ",A2)+13)-FIND(" destination ",A2)-13) -> #VALUE! | I2: =MID(A2,FIND(" interval ",A2)+10,FIND(" ",A2,FIND(" interval ",A2)+10)-FIND(" interval ",A2)-10) -> #VALUE! | J2: =MID(A2,FIND(" probe-timeout ",A2)+15,FIND(" ",A2,FIND(" probe-timeout ",A2)+15)-FIND(" probe-timeout ",A2)-15) -> #VALUE! | K2: =MID(A2,FIND(" recv ",A2)+6,FIND(" send ",A2,FIND(" recv ",A2)+6)-FIND(" recv ",A2)-6) -> #VALUE! | L2: =IFERROR(MID(A2,FIND(" send ",A2)+6,FIND((CHAR(34)&" "),A2,FIND(" send ",A2)+6)-FIND(" send ",A2)-6),MID(A2,FIND(" send ",A2)+6,FIND(" ",A2,FIND(" send ",A2)+6)-FIND(" send ",A2)-6)) -> #VALUE! | M2: =MID(B2,FIND(" timeout ",B2)+9,FIND(" ",B2,FIND(" timeout ",B2)+9)-FIND(" timeout ",B2)-9) -> #VALUE!

Sheet gtmpool
A1: PASTE ONE LINE CONFIG HERE | B1: Substitute last } with " }" | C1: POOL TYPE | D1: POOL NAME | E1: POOL LOAD BALANCING MODE (PREFFERED) | F1: POOL LOAD BALANCING MODE (ALTERNATE) | G1: POOL LOAD BALANCING MODE (FALLBACK) | H1: FALLBACK IP | I1: TTL | J1: MONITOR | K1: POOL MEMBERS (WRAP TEXT TO VIEW MULTILINE) | L1: POOL MEMBER COUNT
B2: =SUBSTITUTE(A2,"}"," }",LEN(A2)-(LEN(SUBSTITUTE(A2,"}","")))) -> #VALUE! | C2: =MID(A2,FIND(" pool ",A2)+6,FIND(" ",A2,FIND(" pool ",A2)+6)-FIND(" pool ",A2)-6) -> #VALUE! | D2: =MID(A2,FIND(" a ",A2)+3,FIND(" ",A2,FIND(" a ",A2)+3)-FIND(" a ",A2)-3) -> #VALUE! | E2: =IFERROR(MID(A2,FIND(" load-balancing-mode ",A2)+21,FIND(" ",A2,FIND(" load-balancing-mode ",A2)+21)-FIND(" load-balancing-mode ",A2)-21),"round-robin") -> round-robin | F2: =IFERROR(MID(A2,FIND(" alternate-mode ",A2)+16,FIND(" ",A2,FIND(" alternate-mode ",A2)+16)-FIND(" alternate-mode ",A2)-16),"round-robin") -> round-robin | G2: =IFERROR(MID(A2,FIND(" fallback-mode ",A2)+15,FIND(" ",A2,FIND(" fallback-mode ",A2)+15)-FIND(" fallback-mode ",A2)-15),"return-to-dns") -> return-to-dns | H2: =IFERROR(MID(A2,FIND(" fallback-ip ",A2)+13,FIND(" ",A2,FIND(" fallback-ip ",A2)+13)-FIND(" fallback-ip ",A2)-13),"0.0.0.0") -> 0.0.0.0 | I2: =IFERROR(MID(A2,FIND(" ttl ",A2)+5,FIND(" ",A2,FIND(" ttl ",A2)+5)-FIND(" ttl ",A2)-5),"") | J2: =IFERROR(MID(B2,FIND(" monitor ",B2)+9,FIND(" ",B2,FIND(" monitor ",B2)+9)-FIND(" monitor ",B2)-9),"") | K2: =SUBSTITUTE(MID(A2,FIND(" members { ",A2)+11,FIND("} }",A2,FIND(" members { ",A2)+11)-FIND(" members { ",A2)-11),"} /","}"&CHAR(10)&"/") -> #VALUE! | L2: =LEN(K2)-LEN(SUBSTITUTE(K2,"order","orde")) -> #VALUE!

Sheet gtmwideip
A1: PASTE ONE LINE CONFIG HERE | B1: Substitute last } with " }" | C1: RECORD TYPE | D1: RECORD | E1: PERSISTENCE | F1: WIDE IP LOAD BALANCING MODE | G1: TTL PERSISTENCE | H1: POOL | I1: POOL COUNT
B2: =SUBSTITUTE(A2,"}"," }",LEN(A2)-(LEN(SUBSTITUTE(A2,"}","")))) -> #VALUE! | C2: =MID(A2,FIND("wideip ",A2)+7,FIND(" ",A2,FIND("wideip ",A2)+7)-FIND("wideip ",A2)-7) -> #VALUE! | D2: =MID(A2,FIND(" a ",A2)+3,FIND(" ",A2,FIND(" a ",A2)+3)-FIND(" a ",A2)-3) -> #VALUE! | E2: =IFERROR(MID(A2,FIND(" persistence ",A2)+13,FIND(" ",A2,FIND(" persistence ",A2)+13)-FIND(" persistence ",A2)-13),"") | F2: =IFERROR(MID(A2,FIND(" pool-lb-mode ",A2)+14,FIND(" ",A2,FIND(" pool-lb-mode ",A2)+14)-FIND(" pool-lb-mode ",A2)-14),"") | G2: =IFERROR(MID(A2,FIND(" ttl-persistence ",A2)+17,FIND(" ",A2,FIND(" ttl-persistence ",A2)+17)-FIND(" ttl-persistence ",A2)-17),"") | H2: =MID(A2,FIND(" pools { ",A2)+9,FIND("} }",A2,FIND(" pools { ",A2)+9)-FIND(" pools { ",A2)-9) -> #VALUE! | I2: =LEN(H2)-LEN(SUBSTITUTE(H2,"order","orde")) -> #VALUE!

Sheet ASM>>>>>>>>>>>>>>>>>>>>>>>>>>>>

Sheet asmpolicy
A1: PASTE ONE LINE CONFIG HERE | B1: POLICY NAME | C1: POLICY NAME WITH ASM PREFIX | D1: PROFILE TYPE | E1: ASM POLICY NAME | F1: POLICY ID | G1: POLICY TEMPLATE | H1: LAST MODIFIED BY | I1: LANGUAGE
B2: =MID(A2,FIND("""",A2)+1,FIND("""",A2,FIND("""",A2)+1)-FIND("""",A2)-1) -> #VALUE! | C2: =SUBSTITUTE(ASM[[#This Row],[POLICY NAME]],"/Common/","/Common/ASM_") -> #VALUE! | D2: ="asm" -> asm | E2: =_xlfn.TEXTBEFORE(_xlfn.TEXTAFTER(SUBSTITUTE(SUBSTITUTE($A2,",","@",2),",","~",2), "@"), "~") -> #N/A | F2: =_xlfn.TEXTBEFORE(_xlfn.TEXTAFTER(SUBSTITUTE(SUBSTITUTE($A2,",","@",3),",","~",3), "@"), "~") -> #N/A | G2: =_xlfn.TEXTBEFORE(_xlfn.TEXTAFTER(SUBSTITUTE(SUBSTITUTE($A2,",","@",4),",","~",4), "@"), "~") -> #N/A | H2: =_xlfn.TEXTBEFORE(_xlfn.TEXTAFTER(SUBSTITUTE(SUBSTITUTE($A2,",","@",6),",","~",6), "@"), "~") -> #N/A | I2: =_xlfn.TEXTBEFORE(_xlfn.TEXTAFTER(SUBSTITUTE(SUBSTITUTE($A2,",","@",16),",","~",16), "@"), "~") -> #N/A
